<mujoco model="pi_plus_23dof_251103">
  <compiler angle="radian" meshdir="../meshes/"/>

    <default>
      <default class="collision">
       <geom group="3"/>
      </default>

    <!-- head motor is 3536-32 -->
    <default class ='head_motor'>
      <joint damping="0.01" armature="0.004383" frictionloss="0.01"/>
    </default>
    <!-- arm motor is 4438-36 -->
    <default class ='arm_motor'>
      <joint damping="0.01" armature="0.008419" frictionloss="0.01"/>
    </default>
    <!-- wrist motor is 4438-30 -->
     <default class ='wrist_motor'>
      <joint damping="0.01" armature="0.008419" frictionloss="0.01"/>
    </default> 
    <!-- leg motor is 5047-36 -->
      <default class ='leg_motor'>
        <joint damping="0.01" armature="0.044277" frictionloss="0.01"/>
    </default>
    <!-- waist motor is 5047-36 -->
      <default class ='waist_motor'>
        <joint damping="0.01" armature="0.044277" frictionloss="0.01"/>
    </default>

    <!-- ankle motor is 5047-36 with link armature-->
      <default class ='ankle_motor'>
        <joint damping="0.01" armature="0.044277" frictionloss="0.01"/>
    </default>
</default>



  <asset>
    <mesh name="base_link" content_type="model/stl" file="base_link.STL"/>
    <mesh name="l_hip_pitch_link" content_type="model/stl" file="l_hip_pitch_link.STL"/>
    <mesh name="l_hip_roll_link" content_type="model/stl" file="l_hip_roll_link.STL"/>
    <mesh name="l_thigh_link" content_type="model/stl" file="l_thigh_link.STL"/>
    <mesh name="l_calf_link" content_type="model/stl" file="l_calf_link.STL"/>
    <mesh name="l_calf_link_5" content_type="model/stl" file="l_calf_link_5.STL"/>
    <mesh name="l_calf_link_2" content_type="model/stl" file="l_calf_link_2.STL"/>
    <mesh name="l_calf_link_6" content_type="model/stl" file="l_calf_link_6.STL"/>
    <mesh name="l_calf_link_8" content_type="model/stl" file="l_calf_link_8.STL"/>
    <mesh name="l_calf_link_9" content_type="model/stl" file="l_calf_link_9.STL"/>
    <mesh name="l_ankle_pitch_link" content_type="model/stl" file="l_ankle_pitch_link.STL"/>
    <mesh name="l_ankle_roll_link" content_type="model/stl" file="l_ankle_roll_link.STL"/>
    <mesh name="l_ankle_roll_link_simplify" content_type="model/stl" file="l_ankle_roll_link_simplify.STL"/>
    <mesh name="r_hip_pitch_link" content_type="model/stl" file="r_hip_pitch_link.STL"/>
    <mesh name="r_hip_roll_link" content_type="model/stl" file="r_hip_roll_link.STL"/>
    <mesh name="r_thigh_link" content_type="model/stl" file="r_thigh_link.STL"/>
    <mesh name="r_calf_link" content_type="model/stl" file="r_calf_link.STL"/>
    <mesh name="r_calf_link_5" content_type="model/stl" file="r_calf_link_5.STL"/>
    <mesh name="r_calf_link_1" content_type="model/stl" file="r_calf_link_1.STL"/>
    <mesh name="r_calf_link_6" content_type="model/stl" file="r_calf_link_6.STL"/>
    <mesh name="r_calf_link_8" content_type="model/stl" file="r_calf_link_8.STL"/>
    <mesh name="r_calf_link_9" content_type="model/stl" file="r_calf_link_9.STL"/>
    <mesh name="r_ankle_pitch_link" content_type="model/stl" file="r_ankle_pitch_link.STL"/>
    <mesh name="r_ankle_roll_link" content_type="model/stl" file="r_ankle_roll_link.STL"/>
    <mesh name="r_ankle_roll_link_simplify" content_type="model/stl" file="r_ankle_roll_link_simplify.STL"/>
    <mesh name="waist_yaw_link" content_type="model/stl" file="waist_yaw_link.STL"/>
    <mesh name="torso_link" content_type="model/stl" file="torso_link.STL"/>
    <mesh name="l_shoulder_pitch_link" content_type="model/stl" file="l_shoulder_pitch_link.STL"/>
    <mesh name="l_shoulder_pitch_link_simplify" content_type="model/stl" file="l_shoulder_pitch_link_simplify.STL"/>
    <mesh name="l_shoulder_roll_link" content_type="model/stl" file="l_shoulder_roll_link.STL"/>
    <mesh name="l_upper_arm_link" content_type="model/stl" file="l_upper_arm_link.STL"/>
    <mesh name="l_elbow_link" content_type="model/stl" file="l_elbow_link.STL"/>
    <mesh name="l_wrist_link" content_type="model/stl" file="l_wrist_link.STL"/>
    <mesh name="r_shoulder_pitch_link" content_type="model/stl" file="r_shoulder_pitch_link.STL"/>
    <mesh name="r_shoulder_pitch_link_simplify" content_type="model/stl" file="r_shoulder_pitch_link_simplify.STL"/>
    <mesh name="r_shoulder_roll_link" content_type="model/stl" file="r_shoulder_roll_link.STL"/>
    <mesh name="r_upper_arm_link" content_type="model/stl" file="r_upper_arm_link.STL"/>
    <mesh name="r_elbow_link" content_type="model/stl" file="r_elbow_link.STL"/>
    <mesh name="r_wrist_link" content_type="model/stl" file="r_wrist_link.STL"/>
    <mesh name="head_yaw_link" content_type="model/stl" file="head_yaw_link.STL"/>
    <mesh name="head_pitch_link" content_type="model/stl" file="head_pitch_link.STL"/>
  </asset>

  <worldbody>
    <body name="base_link" pos="0 0 0.385">
      <inertial pos="-0.00045345 0 -0.038622" quat="0.706552 0.706231 -0.0338779 0.0295487" mass="0.892568" diaginertia="0.00106161 0.00093086 0.000419796"/>
      <joint name="floating_base_joint" type="free"/>
      <geom type="mesh" contype="0" conaffinity="0" group="1" density="0" rgba="0.752941 0.752941 0.752941 1" mesh="base_link"/>
      <geom size="0.03 0.045 0.036" pos="0 0 -0.0369" type="box" rgba="0.752941 0.752941 0.752941 1" class="collision"/>
      <body name="l_hip_pitch_link" pos="0 0.0475 -0.0435">
        <inertial pos="0.00145357 0.0319845 0.00076488" quat="0.656564 0.734884 -0.161749 0.0520159" mass="0.467526" diaginertia="0.000182169 0.000176646 0.000162575"/>
        <joint name="l_hip_pitch_joint" pos="0 0 0" axis="0 1 0" range="-3.12 2.94" actuatorfrcrange="-20 20" damping="0.02" class ='leg_motor'/>
        <geom type="mesh" contype="0" conaffinity="0" group="1" density="0" rgba="0.752941 0.752941 0.752941 1" mesh="l_hip_pitch_link"/>
        <geom type="mesh" rgba="0.752941 0.752941 0.752941 1" mesh="l_hip_pitch_link" class="collision"/>
        <body name="l_hip_roll_link" pos="0 0.034 0">
          <inertial pos="0.00077214 0.00011543 -0.0588086" quat="0.705434 0.0244667 0.0227072 0.70799" mass="0.57399" diaginertia="0.000742894 0.000622613 0.000340363"/>
          <joint name="l_hip_roll_joint" pos="0 0 0" axis="1 0 0" range="-0.17 3.14" actuatorfrcrange="-20 20" damping="0.02" class ='leg_motor'/>
          <geom type="mesh" contype="0" conaffinity="0" group="1" density="0" rgba="0.752941 0.752941 0.752941 1" mesh="l_hip_roll_link"/>
          <geom type="mesh" rgba="0.752941 0.752941 0.752941 1" mesh="l_hip_roll_link" class="collision"/>
          <body name="l_thigh_link" pos="-0.00025 0 -0.0977">
            <inertial pos="0.00101286 -0.00069631 -0.0226902" quat="0.671884 0.739835 0.0244352 -0.024876" mass="0.150079" diaginertia="0.000168825 0.000139137 9.34185e-05"/>
            <joint name="l_thigh_joint" pos="0 0 0" axis="0 0 1" range="-2.87 2.87" actuatorfrcrange="-20 20" damping="0.02" class ='leg_motor'/>
            <geom type="mesh" contype="0" conaffinity="0" group="1" density="0" rgba="0.752941 0.752941 0.752941 1" mesh="l_thigh_link"/>
            <geom type="mesh" rgba="0.752941 0.752941 0.752941 1" mesh="l_thigh_link" class="collision"/>
            <body name="l_calf_link" pos="0 0 -0.045">
              <inertial pos="0.00016713 0.00269948 -0.0648794" quat="0.787713 0.00236306 0.0025537 0.616033" mass="0.857898" diaginertia="0.00409995 0.00409352 0.000230573"/>
              <joint name="l_calf_joint" pos="0 0 0" axis="0 1 0" range="-2.14 2.35" actuatorfrcrange="-20 20" damping="0.02" class ='leg_motor'/>
              <geom type="mesh" contype="0" conaffinity="0" group="1" density="0" rgba="0.752941 0.752941 0.752941 1" mesh="l_calf_link"/>
              <geom type="mesh" rgba="0.752941 0.752941 0.752941 1" mesh="l_calf_link_5"/>
              <geom type="mesh" rgba="0.752941 0.752941 0.752941 1" mesh="l_calf_link_2"/>
              <geom type="mesh" rgba="0.752941 0.752941 0.752941 1" mesh="l_calf_link_6"/>
              <geom type="mesh" rgba="0.752941 0.752941 0.752941 1" mesh="l_calf_link_8"/>
              <geom type="mesh" rgba="0.752941 0.752941 0.752941 1" mesh="l_calf_link_9"/>
              <geom size="0.005 0.01 0.0275" pos="0 0 -0.055" type="box" rgba="0.752941 0.752941 0.752941 1" class="collision"/>
              <body name="l_ankle_pitch_link" pos="0 0 -0.14">
                <inertial pos="0.00655369 -0.00218609 1.446e-05" quat="-0.0129826 0.706801 0.0129996 0.707174" mass="0.165583" diaginertia="0.00027198 0.000184707 0.000120153"/>
                <joint name="l_ankle_pitch_joint" pos="0 0 0" axis="0 1 0" range="-0.97 0.92" actuatorfrcrange="-20 20" damping="0.02" class ='ankle_motor'/>
                <geom type="mesh" contype="0" conaffinity="0" group="1" density="0" rgba="0.752941 0.752941 0.752941 1" mesh="l_ankle_pitch_link"/>
                <geom type="mesh" rgba="0.752941 0.752941 0.752941 1" mesh="l_ankle_pitch_link" class="collision"/>
                <body name="l_ankle_roll_link" pos="0.051 0 0">
                  <inertial pos="0.00374019 0.00021427 -0.00921264" quat="0.551336 0.441164 0.442221 0.553031" mass="0.510618" diaginertia="0.00110702 0.00101595 0.000263949"/>
                  <joint name="l_ankle_roll_joint" pos="0 0 0" axis="1 0 0" range="-0.78 0.78" actuatorfrcrange="-20 20" damping="0.02" class ='ankle_motor'/>
                  <geom type="mesh" contype="0" conaffinity="0" group="1" density="0" rgba="0.752941 0.752941 0.752941 1" mesh="l_ankle_roll_link"/>
                  <geom type="mesh" rgba="0.752941 0.752941 0.752941 1" mesh="l_ankle_roll_link_simplify" class="collision" friction="0.6 0.02 0.01"/>
                </body>
              </body>
            </body>
          </body>
        </body>
      </body>
      <body name="r_hip_pitch_link" pos="0 -0.0475 -0.0435">
        <inertial pos="0.00145354 -0.0324459 0.00076792" quat="0.710852 0.686818 -0.0507116 0.142823" mass="0.467526" diaginertia="0.000182787 0.000177271 0.000162892"/>
        <joint name="r_hip_pitch_joint" pos="0 0 0" axis="0 1 0" range="-3.12 2.94" actuatorfrcrange="-20 20" damping="0.02" class ='leg_motor'/>
        <geom type="mesh" contype="0" conaffinity="0" group="1" density="0" rgba="0.752941 0.752941 0.752941 1" mesh="r_hip_pitch_link"/>
        <geom type="mesh" rgba="0.752941 0.752941 0.752941 1" mesh="r_hip_pitch_link" class="collision"/>
        <body name="r_hip_roll_link" pos="0 -0.034 0">
          <inertial pos="0.00077214 4.589e-05 -0.0588086" quat="0.705548 0.0232449 0.0239355 0.707876" mass="0.57399" diaginertia="0.000742892 0.000622624 0.000340364"/>
          <joint name="r_hip_roll_joint" pos="0 0 0" axis="1 0 0" range="-3.14 0.17" actuatorfrcrange="-20 20" damping="0.02" class ='leg_motor'/>
          <geom type="mesh" contype="0" conaffinity="0" group="1" density="0" rgba="0.752941 0.752941 0.752941 1" mesh="r_hip_roll_link"/>
          <geom type="mesh" rgba="0.752941 0.752941 0.752941 1" mesh="r_hip_roll_link" class="collision"/>
          <body name="r_thigh_link" pos="-0.00025 0 -0.0977">
            <inertial pos="0.00106481 0.00069567 -0.0226878" quat="0.739866 0.67191 0.0240464 -0.0235884" mass="0.150079" diaginertia="0.000168825 0.000139136 9.34185e-05"/>
            <joint name="r_thigh_joint" pos="0 0 0" axis="0 0 1" range="-2.87 2.87" actuatorfrcrange="-20 20" damping="0.02" class ='leg_motor'/>
            <geom type="mesh" contype="0" conaffinity="0" group="1" density="0" rgba="0.752941 0.752941 0.752941 1" mesh="r_thigh_link"/>
            <geom type="mesh" rgba="0.752941 0.752941 0.752941 1" mesh="r_thigh_link"/>
            <body name="r_calf_link" pos="0 0 -0.045">
              <inertial pos="0.00031569 -0.00269949 -0.0648788" quat="0.617883 -0.00139183 -0.000727982 0.786269" mass="0.857898" diaginertia="0.00409995 0.00409335 0.000230752"/>
              <joint name="r_calf_joint" pos="0 0 0" axis="0 1 0" range="-2.14 2.35" actuatorfrcrange="-20 20" damping="0.02" class ='leg_motor'/>
              <geom type="mesh" contype="0" conaffinity="0" group="1" density="0" rgba="0.752941 0.752941 0.752941 1" mesh="r_calf_link"/>
              <geom type="mesh" rgba="0.752941 0.752941 0.752941 1" mesh="r_calf_link_5"/>
              <geom type="mesh" rgba="0.752941 0.752941 0.752941 1" mesh="r_calf_link_1"/>
              <geom type="mesh" rgba="0.752941 0.752941 0.752941 1" mesh="r_calf_link_6"/>
              <geom type="mesh" rgba="0.752941 0.752941 0.752941 1" mesh="r_calf_link_8"/>
              <geom type="mesh" rgba="0.752941 0.752941 0.752941 1" mesh="r_calf_link_9"/>
              <geom size="0.005 0.01 0.0275" pos="0 0 -0.055" type="box" rgba="0.752941 0.752941 0.752941 1" class="collision"/>
              <body name="r_ankle_pitch_link" pos="0 0 -0.14">
                <inertial pos="0.00655369 0.00218609 -1.446e-05" quat="0.0129996 0.707174 -0.0129826 0.706801" mass="0.165583" diaginertia="0.00027198 0.000184707 0.000120153"/>
                <joint name="r_ankle_pitch_joint" pos="0 0 0" axis="0 1 0" range="-0.97 0.92" actuatorfrcrange="-20 20" damping="0.02" class ='ankle_motor'/>
                <geom type="mesh" contype="0" conaffinity="0" group="1" density="0" rgba="0.752941 0.752941 0.752941 1" mesh="r_ankle_pitch_link"/>
                <geom type="mesh" rgba="0.752941 0.752941 0.752941 1" mesh="r_ankle_pitch_link" class="collision"/>
                <body name="r_ankle_roll_link" pos="0.051 0 0">
                  <inertial pos="0.00374019 0.00021427 -0.00921264" quat="0.551336 0.441164 0.442221 0.553031" mass="0.510618" diaginertia="0.00110702 0.00101595 0.000263949"/>
                  <joint name="r_ankle_roll_joint" pos="0 0 0" axis="1 0 0" range="-0.78 0.78" actuatorfrcrange="-20 20" damping="0.02" class ='ankle_motor'/>
                  <geom type="mesh" contype="0" conaffinity="0" group="1" density="0" rgba="0.752941 0.752941 0.752941 1" mesh="r_ankle_roll_link"/>
                  <geom type="mesh" rgba="0.752941 0.752941 0.752941 1" mesh="r_ankle_roll_link_simplify" class="collision" friction="0.6 0.02 0.01"/>
                </body>
              </body>
            </body>
          </body>
        </body>
      </body>
      <body name="waist_yaw_link" pos="0 0 0.02935">
        <site name="imu" size="0.01" pos="-0.0 -0.0 0.0" />
        <inertial pos="-0.0002095 -0.00025712 -0.00446719" quat="0.780898 0.00613466 -0.0339597 0.623705" mass="0.394004" diaginertia="0.000220631 0.000214406 0.000196803"/>
        <joint name="waist_yaw_joint" pos="0 0 0" axis="0 0 1" range="-1.57 1.57" actuatorfrcrange="-20 20" damping="0.02" class ='waist_motor'/>
        <geom type="mesh" contype="0" conaffinity="0" group="1" density="0" rgba="0.752941 0.752941 0.752941 1" mesh="waist_yaw_link"/>
        <geom type="mesh" rgba="0.752941 0.752941 0.752941 1" mesh="waist_yaw_link" class="collision"/>
        <body name="torso_link" pos="0 0 0.02935">
          <inertial pos="0.00621927 4.948e-05 0.0966378" quat="0.593498 0.798506 -0.0572009 0.0829215" mass="2.49973" diaginertia="0.0131651 0.0111729 0.0111391"/>
          <geom type="mesh" contype="0" conaffinity="0" group="1" density="0" rgba="0.752941 0.752941 0.752941 1" mesh="torso_link" class="collision"/>
          <geom type="mesh" rgba="0.752941 0.752941 0.752941 1" mesh="torso_link" />
          <body name="l_shoulder_pitch_link" pos="0 0.1069 0.117">
            <inertial pos="0.00035285 0.0194104 0.00013423" quat="0.0107956 0.706363 0.000958584 0.707767" mass="0.141977" diaginertia="0.000149077 0.000123912 7.49102e-05"/>
            <joint name="l_shoulder_pitch_joint" pos="0 0 0" axis="0 1 0" range="-4.18 1.04" actuatorfrcrange="-10 10" damping="0.02" class ='arm_motor'/>
            <geom type="mesh" contype="0" conaffinity="0" group="1" density="0" rgba="0.752941 0.752941 0.752941 1" mesh="l_shoulder_pitch_link"/>
            <geom type="mesh" rgba="0.752941 0.752941 0.752941 1" mesh="l_shoulder_pitch_link_simplify" />
            <body name="l_shoulder_roll_link" pos="0 0.038 0">
              <inertial pos="0.0013278 0.00036622 -0.0224251" quat="0.997333 0.00588165 0.0267237 0.0676557" mass="0.492424" diaginertia="0.000463117 0.000455113 0.00016181"/>
              <joint name="l_shoulder_roll_joint" pos="0 0 0" axis="1 0 0" range="-0.13 3" actuatorfrcrange="-10 10" damping="0.02" class ='arm_motor'/>
              <geom type="mesh" contype="0" conaffinity="0" group="1" density="0" rgba="0.752941 0.752941 0.752941 1" mesh="l_shoulder_roll_link"/>
              <geom type="mesh" rgba="0.752941 0.752941 0.752941 1" mesh="l_shoulder_roll_link" class="collision"/>
              <body name="l_upper_arm_link" pos="0 0 -0.0724">
                <inertial pos="-6.353e-05 0.00043617 -0.0141229" quat="0.697169 0.716904 -0.000353302 0.00182173" mass="0.162071" diaginertia="0.000197581 0.00014655 0.000120009"/>
                <joint name="l_upper_arm_joint" pos="0 0 0" axis="0 0 1" range="-2.16 2.16" actuatorfrcrange="-10 10" damping="0.02" class ='arm_motor'/>
                <geom type="mesh" contype="0" conaffinity="0" group="1" density="0" rgba="0.752941 0.752941 0.752941 1" mesh="l_upper_arm_link"/>
                <geom type="mesh" rgba="0.752941 0.752941 0.752941 1" mesh="l_upper_arm_link" class="collision"/>
                <body name="l_elbow_link" pos="0 0 -0.038">
                  <inertial pos="-0.00024727 0.00242926 -0.00206736" quat="0.991115 -0.0892301 -0.0170861 0.097149" mass="0.283491" diaginertia="0.000107719 0.00010511 0.00010178"/>
                  <joint name="l_elbow_joint" pos="0 0 0" axis="0 1 0" range="-2 2" actuatorfrcrange="-10 10" damping="0.02" class ='arm_motor'/>
                  <geom type="mesh" contype="0" conaffinity="0" group="1" density="0" rgba="0.752941 0.752941 0.752941 1" mesh="l_elbow_link"/>
                  <geom type="mesh" rgba="0.752941 0.752941 0.752941 1" mesh="l_elbow_link" class="collision"/>
                  <body name="l_wrist_link" pos="0 0 -0.029">
                    <inertial pos="-1.174e-05 2.952e-05 -0.0420002" quat="0.999999 0.000530118 0.000193373 -0.00106594" mass="0.0729616" diaginertia="0.0001142 0.00011418 1.04699e-05"/>
                    <joint name="l_wrist_joint" pos="0 0 0" axis="0 0 1" range="-1.57 1.57" actuatorfrcrange="-10 10" damping="0.02" class ='wrist_motor'/>
                    <geom type="mesh" contype="0" conaffinity="0" group="1" density="0" rgba="0.752941 0.752941 0.752941 1" mesh="l_wrist_link"/>
                    <geom type="mesh" rgba="0.752941 0.752941 0.752941 1" mesh="l_wrist_link" class="collision"/>
                  </body>
                </body>
              </body>
            </body>
          </body>
          <body name="r_shoulder_pitch_link" pos="0 -0.1069 0.117">
            <inertial pos="0.00035285 -0.0194104 0.00013423" quat="-0.0107956 0.706363 -0.000958584 0.707767" mass="0.141977" diaginertia="0.000149077 0.000123912 7.49102e-05"/>
            <joint name="r_shoulder_pitch_joint" pos="0 0 0" axis="0 1 0" range="-4.18 1.04" actuatorfrcrange="-10 10" damping="0.02" class ='arm_motor'/>
            <geom type="mesh" contype="0" conaffinity="0" group="1" density="0" rgba="0.752941 0.752941 0.752941 1" mesh="r_shoulder_pitch_link"/>
            <geom type="mesh" rgba="0.752941 0.752941 0.752941 1" mesh="r_shoulder_pitch_link_simplify" />
            <body name="r_shoulder_roll_link" pos="0 -0.038 0">
              <inertial pos="0.00132741 -0.00037058 -0.022427" quat="0.999586 0.00982407 0.0270368 0.000987432" mass="0.492402" diaginertia="0.000462921 0.000455303 0.000161707"/>
              <joint name="r_shoulder_roll_joint" pos="0 0 0" axis="1 0 0" range="-3 0.13" actuatorfrcrange="-10 10" damping="0.02" class ='arm_motor'/>
              <geom type="mesh" contype="0" conaffinity="0" group="1" density="0" rgba="0.752941 0.752941 0.752941 1" mesh="r_shoulder_roll_link"/>
              <geom type="mesh" rgba="0.752941 0.752941 0.752941 1" mesh="r_shoulder_roll_link" class="collision"/>
              <body name="r_upper_arm_link" pos="0 0 -0.0724">
                <inertial pos="-6.353e-05 -0.00043617 -0.0141229" quat="0.716904 0.697169 -0.00182173 0.000353302" mass="0.162071" diaginertia="0.000197581 0.00014655 0.000120009"/>
                <joint name="r_upper_arm_joint" pos="0 0 0" axis="0 0 1" range="-2.16 2.16" actuatorfrcrange="-10 10" damping="0.02" class ='arm_motor'/>
                <geom type="mesh" contype="0" conaffinity="0" group="1" density="0" rgba="0.752941 0.752941 0.752941 1" mesh="r_upper_arm_link"/>
                <geom type="mesh" rgba="0.752941 0.752941 0.752941 1" mesh="r_upper_arm_link" class="collision"/>
                <body name="r_elbow_link" pos="0 0 -0.038">
                  <inertial pos="0.00024727 -0.00242926 -0.00206736" quat="0.991115 0.0892301 0.0170861 0.097149" mass="0.283491" diaginertia="0.000107719 0.00010511 0.00010178"/>
                  <joint name="r_elbow_joint" pos="0 0 0" axis="0 1 0" range="-2 2" actuatorfrcrange="-10 10" damping="0.02" class ='arm_motor'/>
                  <geom type="mesh" contype="0" conaffinity="0" group="1" density="0" rgba="0.752941 0.752941 0.752941 1" mesh="r_elbow_link"/>
                  <geom type="mesh" rgba="0.752941 0.752941 0.752941 1" mesh="r_elbow_link" class="collision"/>
                  <body name="r_wrist_link" pos="0 0 -0.029">
                    <inertial pos="-3.138e-05 -4.98e-06 -0.0420002" quat="0.707518 0.00034064 0.000477453 0.706695" mass="0.0729616" diaginertia="0.0001142 0.00011418 1.04699e-05"/>
                    <joint name="r_wrist_joint" pos="0 0 0" axis="0 0 1" range="-1.57 1.57" actuatorfrcrange="-10 10" damping="0.02" class ='wrist_motor'/>
                    <geom type="mesh" contype="0" conaffinity="0" group="1" density="0" rgba="0.752941 0.752941 0.752941 1" mesh="r_wrist_link"/>
                    <geom type="mesh" rgba="0.752941 0.752941 0.752941 1" mesh="r_wrist_link" class="collision"/>
                  </body>
                </body>
              </body>
            </body>
          </body>
        
          <body name="head_yaw_link" pos="0 0.00025 0.1981">
            <inertial pos="-8.774e-05 0.0001841 0.0230633" quat="0.952947 -0.298994 -0.00310213 0.0498495" mass="0.184046" diaginertia="3.97163e-05 3.66911e-05 3.18526e-05"/>
            <joint name="head_yaw_joint" pos="0 0 0" axis="0 0 1" range="-1.39 1.39" actuatorfrcrange="-3 3" damping="0.02" class ='head_motor'/>
            <geom type="mesh" contype="0" conaffinity="0" group="1" density="0" rgba="0.752941 0.752941 0.752941 1" mesh="head_yaw_link"/>
            <geom type="mesh" rgba="0.752941 0.752941 0.752941 1" mesh="head_yaw_link" class="collision"/>
            <body name="head_pitch_link" pos="0 0 0.0255">
              <inertial pos="0.0326414 -0.0021897 0.0505947" quat="0.208172 0.6778 -0.200286 0.676119" mass="0.483813" diaginertia="0.0018082 0.00110466 0.00104476"/>
              <joint name="head_pitch_joint" pos="0 0 0" axis="0 1 0" range="-0.34 1.26" actuatorfrcrange="-3 3" damping="0.02" class ='head_motor'/>
              <geom type="mesh" contype="0" conaffinity="0" group="1" density="0" rgba="0.752941 0.752941 0.752941 1" mesh="head_pitch_link"/>
              <geom type="mesh" rgba="0.752941 0.752941 0.752941 1" mesh="head_pitch_link" class="collision"/>
            </body>
          </body>
        </body>
      </body>
    </body>
    
  </worldbody>
   <actuator>
      <motor name="l_hip_pitch_joint" joint="l_hip_pitch_joint" gear="1" ctrllimited="true" ctrlrange="-20 20" />
      <motor name="l_hip_roll_joint" joint="l_hip_roll_joint" gear="1" ctrllimited="true" ctrlrange="-20 20" />
      <motor name="l_thigh_joint" joint="l_thigh_joint" gear="1" ctrllimited="true" ctrlrange="-20 20" />
      <motor name="l_calf_joint" joint="l_calf_joint" gear="1" ctrllimited="true" ctrlrange="-20 20" />
      <motor name="l_ankle_pitch_joint" joint="l_ankle_pitch_joint" gear="1" ctrllimited="true" ctrlrange="-20 20" />
      <motor name="l_ankle_roll_joint" joint="l_ankle_roll_joint" gear="1" ctrllimited="true" ctrlrange="-20 20" />

      <motor name="r_hip_pitch_joint" joint="r_hip_pitch_joint" gear="1" ctrllimited="true" ctrlrange="-20 20" />
      <motor name="r_hip_roll_joint" joint="r_hip_roll_joint" gear="1" ctrllimited="true" ctrlrange="-20 20" />
      <motor name="r_thigh_joint" joint="r_thigh_joint" gear="1" ctrllimited="true" ctrlrange="-20 20" />
      <motor name="r_calf_joint" joint="r_calf_joint" gear="1" ctrllimited="true" ctrlrange="-20 20" />
      <motor name="r_ankle_pitch_joint" joint="r_ankle_pitch_joint" gear="1" ctrllimited="true" ctrlrange="-20 20" />
      <motor name="r_ankle_roll_joint" joint="r_ankle_roll_joint" gear="1" ctrllimited="true" ctrlrange="-20 20" />

      <motor name="waist_yaw_joint" joint="waist_yaw_joint" gear="1" ctrllimited="true" ctrlrange="-30 30" />

      <motor name="l_shoulder_pitch_joint" joint="l_shoulder_pitch_joint" gear="1" ctrllimited="true" ctrlrange="-20 20" />
      <motor name="l_shoulder_roll_joint" joint="l_shoulder_roll_joint" gear="1" ctrllimited="true" ctrlrange="-20 20" />
      <motor name="l_upper_arm_joint" joint="l_upper_arm_joint" gear="1" ctrllimited="true" ctrlrange="-20 20" />
      <motor name="l_elbow_joint" joint="l_elbow_joint" gear="1" ctrllimited="true" ctrlrange="-20 20" />
      <motor name="l_wrist_joint" joint="l_wrist_joint" gear="1" ctrllimited="true" ctrlrange="-20 20" />


      <motor name="r_shoulder_pitch_joint" joint="r_shoulder_pitch_joint" gear="1" ctrllimited="true" ctrlrange="-20 20" />
      <motor name="r_shoulder_roll_joint" joint="r_shoulder_roll_joint" gear="1" ctrllimited="true" ctrlrange="-20 20" />
      <motor name="r_upper_arm_joint" joint="r_upper_arm_joint" gear="1" ctrllimited="true" ctrlrange="-20 20" />
      <motor name="r_elbow_joint" joint="r_elbow_joint" gear="1" ctrllimited="true" ctrlrange="-20 20" />
      <motor name="r_wrist_joint" joint="r_wrist_joint" gear="1" ctrllimited="true" ctrlrange="-20 20" />

      <motor name="head_yaw_joint" joint="head_yaw_joint" gear="1" ctrllimited="true" ctrlrange="-10 10" />
      <motor name="head_pitch_joint" joint="head_pitch_joint" gear="1" ctrllimited="true" ctrlrange="-10 10" />
   </actuator>
   <sensor>
   <!-- Position sensors -->
    <actuatorpos name="l_hip_pitch_joint_p" actuator="l_hip_pitch_joint" user="13"/>
    <actuatorpos name="l_hip_roll_joint_p" actuator="l_hip_roll_joint" user="13"/>
    <actuatorpos name="l_thigh_joint_p" actuator="l_thigh_joint" user="13"/>
    <actuatorpos name="l_calf_joint_p" actuator="l_calf_joint" user="13"/>
    <actuatorpos name="l_ankle_pitch_joint_p" actuator="l_ankle_pitch_joint" user="13"/>
    <actuatorpos name="l_ankle_roll_joint_p" actuator="l_ankle_roll_joint" user="13"/>


    <actuatorpos name="r_hip_pitch_joint_p" actuator="r_hip_pitch_joint" user="13"/>
    <actuatorpos name="r_hip_roll_joint_p" actuator="r_hip_roll_joint" user="13"/>
    <actuatorpos name="r_thigh_joint_p" actuator="r_thigh_joint" user="13"/>
    <actuatorpos name="r_calf_joint_p" actuator="r_calf_joint" user="13"/>
    <actuatorpos name="r_ankle_pitch_joint_p" actuator="r_ankle_pitch_joint" user="13"/>
    <actuatorpos name="r_ankle_roll_joint_p" actuator="r_ankle_roll_joint" user="13"/>

    <actuatorpos name="waist_yaw_joint_p" actuator="waist_yaw_joint" user="13"/>

    <actuatorpos name="l_shoulder_pitch_joint_p" actuator="l_shoulder_pitch_joint" user="13"/>
    <actuatorpos name="l_shoulder_roll_joint_p" actuator="l_shoulder_roll_joint" user="13"/>
    <actuatorpos name="l_upper_arm_joint_p" actuator="l_upper_arm_joint" user="13"/>
    <actuatorpos name="l_elbow_joint_p" actuator="l_elbow_joint" user="13"/>
    <actuatorpos name="l_wrist_joint_p" actuator="l_wrist_joint" user="13"/>

    <actuatorpos name="r_shoulder_pitch_joint_p" actuator="r_shoulder_pitch_joint" user="13"/>
    <actuatorpos name="r_shoulder_roll_joint_p" actuator="r_shoulder_roll_joint" user="13"/>
    <actuatorpos name="r_upper_arm_joint_p" actuator="r_upper_arm_joint" user="13"/>
    <actuatorpos name="r_elbow_joint_p" actuator="r_elbow_joint" user="13"/>
    <actuatorpos name="r_wrist_joint_p" actuator="r_wrist_joint" user="13"/>

    <actuatorpos name="head_yaw_joint_p" actuator="head_yaw_joint" user="13"/>
    <actuatorpos name="head_pitch_joint_p" actuator="head_pitch_joint" user="13"/>

    <!-- Velocity sensors -->
    <actuatorvel name="l_hip_pitch_joint_v" actuator="l_hip_pitch_joint" user="13" noise="1e-3"/>
    <actuatorvel name="l_hip_roll_joint_v" actuator="l_hip_roll_joint" user="13" noise="1e-3"/>
    <actuatorvel name="l_thigh_joint_v" actuator="l_thigh_joint" user="13" noise="1e-3"/>
    <actuatorvel name="l_calf_joint_v" actuator="l_calf_joint" user="13" noise="1e-3"/>
    <actuatorvel name="l_ankle_pitch_joint_v" actuator="l_ankle_pitch_joint" user="13" noise="1e-3"/>
    <actuatorvel name="l_ankle_roll_joint_v" actuator="l_ankle_roll_joint" user="13" noise="1e-3"/>
    
    <actuatorvel name="r_hip_pitch_joint_v" actuator="r_hip_pitch_joint" user="13" noise="1e-3"/>
    <actuatorvel name="r_hip_roll_joint_v" actuator="r_hip_roll_joint" user="13" noise="1e-3"/>
    <actuatorvel name="r_thigh_joint_v" actuator="r_thigh_joint" user="13" noise="1e-3"/>
    <actuatorvel name="r_calf_joint_v" actuator="r_calf_joint" user="13" noise="1e-3"/>
    <actuatorvel name="r_ankle_pitch_joint_v" actuator="r_ankle_pitch_joint" user="13" noise="1e-3"/>
    <actuatorvel name="r_ankle_roll_joint_v" actuator="r_ankle_roll_joint" user="13" noise="1e-3"/>

    <actuatorpos name="waist_yaw_joint_v" actuator="waist_yaw_joint" user="13"/>

    <actuatorvel name="l_shoulder_pitch_joint_v" actuator="l_shoulder_pitch_joint" user="13" noise="1e-3"/>
    <actuatorvel name="l_shoulder_roll_joint_v" actuator="l_shoulder_roll_joint" user="13" noise="1e-3"/>
    <actuatorvel name="l_upper_arm_joint_v" actuator="l_upper_arm_joint" user="13" noise="1e-3"/>
    <actuatorvel name="l_elbow_joint_v" actuator="l_elbow_joint" user="13" noise="1e-3"/>
    <actuatorvel name="l_wrist_joint_v" actuator="l_wrist_joint" user="13" noise="1e-3"/>

    <actuatorvel name="r_shoulder_pitch_joint_v" actuator="r_shoulder_pitch_joint" user="13" noise="1e-3"/>
    <actuatorvel name="r_shoulder_roll_joint_v" actuator="r_shoulder_roll_joint" user="13" noise="1e-3"/>
    <actuatorvel name="r_upper_arm_joint_v" actuator="r_upper_arm_joint" user="13" noise="1e-3"/>
    <actuatorvel name="r_elbow_joint_v" actuator="r_elbow_joint" user="13" noise="1e-3"/>
    <actuatorvel name="r_wrist_joint_v" actuator="r_wrist_joint" user="13" noise="1e-3"/>

    <actuatorvel name="head_yaw_joint_v" actuator="head_yaw_joint" user="13" noise="1e-3"/>
    <actuatorvel name="head_pitch_joint_v" actuator="head_pitch_joint" user="13" noise="1e-3"/>

    <!-- Force sensors -->
    <actuatorfrc name="l_hip_pitch_joint_f" actuator="l_hip_pitch_joint" user="13" noise="1e-3"/>
    <actuatorfrc name="l_hip_roll_joint_f" actuator="l_hip_roll_joint" user="13" noise="1e-3"/>
    <actuatorfrc name="l_thigh_joint_f" actuator="l_thigh_joint" user="13" noise="1e-3"/>
    <actuatorfrc name="l_calf_joint_f" actuator="l_calf_joint" user="13" noise="1e-3"/>
    <actuatorfrc name="l_ankle_pitch_joint_f" actuator="l_ankle_pitch_joint" user="13" noise="1e-3"/>
    <actuatorfrc name="l_ankle_roll_joint_f" actuator="l_ankle_roll_joint" user="13" noise="1e-3"/>
    
    <actuatorfrc name="r_hip_pitch_joint_f" actuator="r_hip_pitch_joint" user="13" noise="1e-3"/>
    <actuatorfrc name="r_hip_roll_joint_f" actuator="r_hip_roll_joint" user="13" noise="1e-3"/>
    <actuatorfrc name="r_thigh_joint_f" actuator="r_thigh_joint" user="13" noise="1e-3"/>
    <actuatorfrc name="r_calf_joint_f" actuator="r_calf_joint" user="13" noise="1e-3"/>
    <actuatorfrc name="r_ankle_pitch_joint_f" actuator="r_ankle_pitch_joint" user="13" noise="1e-3"/>
    <actuatorfrc name="r_ankle_roll_joint_f" actuator="r_ankle_roll_joint" user="13" noise="1e-3"/>

    <actuatorpos name="waist_yaw_joint_f" actuator="waist_yaw_joint" user="13"/>

    <actuatorfrc name="l_shoulder_pitch_joint_f" actuator="l_shoulder_pitch_joint" user="13" noise="1e-3"/>
    <actuatorfrc name="l_shoulder_roll_joint_f" actuator="l_shoulder_roll_joint" user="13" noise="1e-3"/>
    <actuatorfrc name="l_upper_arm_joint_f" actuator="l_upper_arm_joint" user="13" noise="1e-3"/>
    <actuatorfrc name="l_elbow_joint_f" actuator="l_elbow_joint" user="13" noise="1e-3"/>
    <actuatorfrc name="l_wrist_joint_f" actuator="l_wrist_joint" user="13"/>


    <actuatorfrc name="r_shoulder_pitch_joint_f" actuator="r_shoulder_pitch_joint" user="13" noise="1e-3"/>
    <actuatorfrc name="r_shoulder_roll_joint_f" actuator="r_shoulder_roll_joint" user="13" noise="1e-3"/>
    <actuatorfrc name="r_upper_arm_joint_f" actuator="r_upper_arm_joint" user="13" noise="1e-3"/>
    <actuatorfrc name="r_elbow_joint_f" actuator="r_elbow_joint" user="13" noise="1e-3"/>
    <actuatorfrc name="r_wrist_joint_f" actuator="r_wrist_joint" user="13"/>

    <actuatorfrc name="head_yaw_joint_f" actuator="head_yaw_joint" user="13" noise="1e-3"/>
    <actuatorfrc name="head_pitch_joint_f" actuator="head_pitch_joint" user="13" noise="1e-3"/>

    <framequat name='orientation' objtype='site' noise='0.001' objname='imu'/>
    <framepos name='position' objtype='site' noise='0.001' objname='imu'/>
    <gyro name='angular-velocity' site='imu' noise='0.005' cutoff='34.9'/>
    <velocimeter name='linear-velocity' site='imu' noise='0.001' cutoff='30'/>
    <accelerometer name='linear-acceleration' site='imu' noise='0.005' cutoff='157'/>
    <magnetometer name='magnetometer' site='imu'/>

  </sensor>
   <!-- setup scene -->
  <statistic center="1.0 0.7 1.0" extent="0.8"/>
  <visual>
    <headlight diffuse="0.6 0.6 0.6" ambient="0.1 0.1 0.1" specular="0.9 0.9 0.9"/>
    <rgba haze="0.15 0.25 0.35 1"/>
    <global azimuth="-140" elevation="-20"/>
  </visual>
  <asset>
    <texture type="skybox" builtin="flat" rgb1="0 0 0" rgb2="0 0 0" width="512" height="3072"/>
    <texture type="2d" name="groundplane" builtin="checker" mark="edge" rgb1="0.2 0.3 0.4" rgb2="0.1 0.2 0.3" markrgb="0.8 0.8 0.8" width="300" height="300"/>
    <material name="groundplane" texture="groundplane" texuniform="true" texrepeat="5 5" reflectance="0.2"/>
  </asset>
  <worldbody>
    <light pos="1 0 3.5" dir="0 0 -1" directional="true"/>
    <geom contype="15" conaffinity="15"  name="floor" size="0 0 0.05" type="plane" material="groundplane"/>
  </worldbody>


</mujoco>
