<mujoco model="pi">
  <compiler angle="radian" meshdir="../meshes/"/>


  <default>
    <default class="collision">
       <geom group="1"/>
      </default>
    <default class="leg_motor">
      <joint damping="0.01" armature="0.044277" frictionloss="0.01" />
    </default>
  </default>

  <asset>
    <mesh name="base_link" content_type="model/stl" file="baselink_1.STL"/>
    <mesh name="l_hip_pitch_link" content_type="model/stl" file="l_hip_pitch_link.STL"/>
    <mesh name="l_hip_roll_link" content_type="model/stl" file="l_hip_roll_link.STL"/>
    <mesh name="l_thigh_link" content_type="model/stl" file="l_thigh_link.STL"/>
    <mesh name="l_calf_link" content_type="model/stl" file="l_calf_link.STL"/>
    <mesh name="l_ankle_pitch_link" content_type="model/stl" file="l_ankle_pitch_link.STL"/>
    <mesh name="l_ankle_roll_link" content_type="model/stl" file="l_ankle_roll_link.STL"/>
    <mesh name="r_hip_pitch_link" content_type="model/stl" file="r_hip_pitch_link.STL"/>
    <mesh name="r_hip_roll_link" content_type="model/stl" file="r_hip_roll_link.STL"/>
    <mesh name="r_thigh_link" content_type="model/stl" file="r_thigh_link.STL"/>
    <mesh name="r_calf_link" content_type="model/stl" file="r_calf_link.STL"/>
    <mesh name="r_ankle_pitch_link" content_type="model/stl" file="r_ankle_pitch_link.STL"/>
    <mesh name="r_ankle_roll_link" content_type="model/stl" file="r_ankle_roll_link.STL"/>
  </asset>

  <worldbody>
    <body name="base_link" pos="0 0 0.39">
      <site name="imu" size="0.01" pos="-0.0 -0.0 0.0" />
      <inertial pos="0.00511413 -0.000220982 0.0966471" quat="0.999251 0.00280782 0.0374162 0.0094174" mass="3.44087" diaginertia="0.0459459 0.0431088 0.00967703"/>
      <joint name="floating_base_joint" type="free" limited="false" actuatorfrclimited="false"/>
      <geom type="mesh" contype="0" conaffinity="0" group="1" density="0" rgba="1 1 1 1" mesh="base_link"/>
      <geom size="0.085 0.055 0.075" pos="0 0 0.08" type="box" rgba="1 1 1 1" class="collision"/>
      <body name="l_hip_pitch_link" pos="-5.1979e-05 0.0233 -0.033">
        <inertial pos="0.00086268 0.0544191 -0.00025859" quat="-0.0385995 0.705608 0.0295548 0.706932" mass="0.389686" diaginertia="0.000128344 0.000105107 0.000100719"/>
        <joint name="l_hip_pitch_joint" pos="0 0 0" axis="0 1 0" range="-1.5 1.5" actuatorfrcrange="-21 21" class="leg_motor"/>
        <geom type="mesh" contype="0" conaffinity="0" group="1" density="0" rgba="0.75294 0.75294 0.75294 1" mesh="l_hip_pitch_link"/>
        <geom size="0.025 0.025 0.025" pos="0 0.06 0" type="box" rgba="0.75294 0.75294 0.75294 1" class="collision"/>
        <body name="l_hip_roll_link" pos="0 0.0568 0">
          <inertial pos="-0.00207707 0.00026598 -0.0608194" quat="0.699248 -0.0752466 -0.0779987 0.706616" mass="0.388516" diaginertia="0.000333211 0.000277592 0.000128507"/>
          <joint name="l_hip_roll_joint" pos="0 0 0" axis="1 0 0" range="-0.38 1.2" actuatorfrcrange="-21 21" class="leg_motor"/>
          <geom type="mesh" contype="0" conaffinity="0" group="1" density="0" rgba="0.75294 0.75294 0.75294 1" mesh="l_hip_roll_link"/>
          <geom size="0.025 0.025 0.02" pos="0 0 -0.065" type="box" rgba="0.75294 0.75294 0.75294 1" class="collision"/>
          <body name="l_thigh_link" pos="0 0 -0.06925">
            <inertial pos="0 -0.00115822 -0.047559" quat="0.67539 0.737461 0 0" mass="0.112709" diaginertia="0.00012497 9.46626e-05 5.79174e-05"/>
            <joint name="l_thigh_joint" pos="0 0 0" axis="0 0 1" range="-1 1" actuatorfrcrange="-21 21" class="leg_motor"/>
            <geom type="mesh" contype="0" conaffinity="0" group="1" density="0" rgba="0.75294 0.75294 0.75294 1" mesh="l_thigh_link"/>
            <geom size="0.02 0.03 0.0025" pos="0 0 -0.025" type="box" rgba="0.75294 0.75294 0.75294 1" class="collision"/>
            <body name="l_calf_link" pos="0 0 -0.07025">
              <inertial pos="0.00026627 0.00386537 -0.0697121" quat="0.999984 0.00311529 -0.000122098 0.00472349" mass="0.813742" diaginertia="0.00352123 0.00349959 0.000174551"/>
              <joint name="l_calf_joint" pos="0 0 0" axis="0 1 0" range="0 2.2" actuatorfrcrange="-21 21" class="leg_motor"/>
              <geom type="mesh" contype="0" conaffinity="0" group="1" density="0" rgba="0.75294 0.75294 0.75294 1" mesh="l_calf_link"/>
              <geom size="0.025 0.025 0.025" type="box" rgba="0.75294 0.75294 0.75294 1" class="collision"/>
              <body name="l_ankle_pitch_link" pos="0 0 -0.14">
                <inertial pos="0.00467932 -0.00077699 0" quat="-0.00221869 0.707103 0.00221869 0.707103" mass="0.175924" diaginertia="0.00030766 0.000221794 0.000119806"/>
                <joint name="l_ankle_pitch_joint" pos="0 0 0" axis="0 1 0" range="-0.8 0.8" actuatorfrcrange="-21 21" class="leg_motor"/>
                <geom type="mesh" contype="0" conaffinity="0" group="1" density="0" rgba="0.75294 0.75294 0.75294 1" mesh="l_ankle_pitch_link"/>
                <geom size="0.035 0.0325 0.0225" type="box" rgba="0.75294 0.75294 0.75294 1" class="collision"/>
                <body name="l_ankle_roll_link" pos="0.07525 0 0">
                  <inertial pos="-0.0238368 0.00019256 -0.0144649" quat="0.5599 0.43068 0.434161 0.559045" mass="0.518685" diaginertia="0.00113169 0.00103133 0.000283273"/>
                  <joint name="l_ankle_roll_joint" pos="0 0 0" axis="1 0 0" range="-0.6 0.6" actuatorfrcrange="-21 21" class="leg_motor"/>
                  <geom type="mesh" contype="0" conaffinity="0" group="1" density="0" rgba="0.75294 0.75294 0.75294 1" mesh="l_ankle_roll_link"/>
                  <geom size="0.085 0.035 0.004" pos="-0.05 0 -0.045" type="box" rgba="0.75294 0.75294 0.75294 1" class="collision"/>
                  <geom size="0.025 0.035 0.03" pos="0.01 0 -0.005" type="box" rgba="0.75294 0.75294 0.75294 1" class="collision"/>
                </body>
              </body>
            </body>
          </body>
        </body>
      </body>
      <body name="r_hip_pitch_link" pos="-5.1979e-05 -0.0233 -0.033">
        <inertial pos="0.00089428 -0.0552774 -0.00027276" quat="-0.0190163 0.705972 -0.0283274 0.707417" mass="0.369998" diaginertia="0.000108547 9.80557e-05 8.30673e-05"/>
        <joint name="r_hip_pitch_joint" pos="0 0 0" axis="0 1 0" range="-1.5 1.5" actuatorfrcrange="-21 21" class="leg_motor"/>
        <geom type="mesh" contype="0" conaffinity="0" group="1" density="0" rgba="0.75294 0.75294 0.75294 1" mesh="r_hip_pitch_link"/>
        <geom size="0.025 0.025 0.025" pos="0 -0.06 0" type="box" rgba="0.75294 0.75294 0.75294 1" class="collision"/>
        <body name="r_hip_roll_link" pos="0.00025 -0.0568 0">
          <inertial pos="-0.00180153 0.00025956 -0.0608194" quat="0.705929 -0.0791259 -0.0825487 0.698992" mass="0.388516" diaginertia="0.000334209 0.00027814 0.000128441"/>
          <joint name="r_hip_roll_joint" pos="0 0 0" axis="1 0 0" range="-0.38 1.2" actuatorfrcrange="-21 21" class="leg_motor"/>
          <geom type="mesh" contype="0" conaffinity="0" group="1" density="0" rgba="0.75294 0.75294 0.75294 1" mesh="r_hip_roll_link"/>
          <geom size="0.025 0.025 0.02" pos="0 0 -0.065" type="box" rgba="0.75294 0.75294 0.75294 1" class="collision"/>
          <body name="r_thigh_link" pos="-0.00025 0 -0.06925">
            <inertial pos="0 0.00116854 -0.047559" quat="0.73728 0.675588 0 0" mass="0.112709" diaginertia="0.00012496 9.46591e-05 5.79209e-05"/>
            <joint name="r_thigh_joint" pos="0 0 0" axis="0 0 1" range="-1 1" actuatorfrcrange="-21 21" class="leg_motor"/>
            <geom type="mesh" contype="0" conaffinity="0" group="1" density="0" rgba="0.75294 0.75294 0.75294 1" mesh="r_thigh_link"/>
            <geom size="0.02 0.03 0.0025" pos="0 0 -0.025" type="box" rgba="0.75294 0.75294 0.75294 1" class="collision"/>
            <body name="r_calf_link" pos="0 -0.0027 -0.07025">
              <inertial pos="-0.00026627 -0.00116537 -0.0697121" quat="0.999984 -0.00311529 0.000122098 0.00472349" mass="0.813742" diaginertia="0.00352123 0.00349959 0.000174551"/>
              <joint name="r_calf_joint" pos="0 0 0" axis="0 1 0" range="0 2.2" actuatorfrcrange="-21 21" class="leg_motor"/>
              <geom type="mesh" contype="0" conaffinity="0" group="1" density="0" rgba="0.75294 0.75294 0.75294 1" mesh="r_calf_link"/>
              <geom size="0.025 0.025 0.025" type="box" rgba="0.75294 0.75294 0.75294 1" class="collision"/>
              <body name="r_ankle_pitch_link" pos="0 0 -0.14">
                <inertial pos="0.00467932 0.00347699 0" quat="0.00221869 0.707103 -0.00221869 0.707103" mass="0.175924" diaginertia="0.00030766 0.000221794 0.000119806"/>
                <joint name="r_ankle_pitch_joint" pos="0 0 0" axis="0 1 0" range="-0.8 0.8" actuatorfrcrange="-21 21" class="leg_motor"/>
                <geom type="mesh" contype="0" conaffinity="0" group="1" density="0" rgba="0.75294 0.75294 0.75294 1" mesh="r_ankle_pitch_link"/>
                <geom size="0.035 0.0325 0.0225" type="box" rgba="0.75294 0.75294 0.75294 1" class="collision"/>
                <body name="r_ankle_roll_link" pos="0.07525 0.0027 0">
                  <inertial pos="-0.0238368 0.00019256 -0.0144649" quat="0.5599 0.43068 0.434161 0.559045" mass="0.518685" diaginertia="0.00113169 0.00103133 0.000283273"/>
                  <joint name="r_ankle_roll_joint" pos="0 0 0" axis="1 0 0" range="-0.6 0.6" actuatorfrcrange="-21 21" class="leg_motor"/>
                  <geom type="mesh" contype="0" conaffinity="0" group="1" density="0" rgba="0.75294 0.75294 0.75294 1" mesh="r_ankle_roll_link"/>
                  <geom size="0.085 0.035 0.004" pos="-0.05 0 -0.045" type="box" rgba="0.75294 0.75294 0.75294 1" class="collision"/>
                  <geom size="0.025 0.035 0.03" pos="0.01 0 -0.005" type="box" rgba="0.75294 0.75294 0.75294 1" class="collision"/>
                </body>
              </body>
            </body>
          </body>
        </body>
      </body>
    </body>
  </worldbody>
  <actuator>
      <motor name="l_hip_pitch_joint" joint="l_hip_pitch_joint" gear="1" ctrllimited="true" ctrlrange="-20 20" />
      <motor name="l_hip_roll_joint" joint="l_hip_roll_joint" gear="1" ctrllimited="true" ctrlrange="-20 20" />
      <motor name="l_thigh_joint" joint="l_thigh_joint" gear="1" ctrllimited="true" ctrlrange="-20 20" />
      <motor name="l_calf_joint" joint="l_calf_joint" gear="1" ctrllimited="true" ctrlrange="-20 20" />
      <motor name="l_ankle_pitch_joint" joint="l_ankle_pitch_joint" gear="1" ctrllimited="true" ctrlrange="-20 20" />
      <motor name="l_ankle_roll_joint" joint="l_ankle_roll_joint" gear="1" ctrllimited="true" ctrlrange="-20 20" />
          
      <motor name="r_hip_pitch_joint" joint="r_hip_pitch_joint" gear="1" ctrllimited="true" ctrlrange="-20 20" />
      <motor name="r_hip_roll_joint" joint="r_hip_roll_joint" gear="1" ctrllimited="true" ctrlrange="-20 20" />
      <motor name="r_thigh_joint" joint="r_thigh_joint" gear="1" ctrllimited="true" ctrlrange="-20 20" />
      <motor name="r_calf_joint" joint="r_calf_joint" gear="1" ctrllimited="true" ctrlrange="-20 20" />
      <motor name="r_ankle_pitch_joint" joint="r_ankle_pitch_joint" gear="1" ctrllimited="true" ctrlrange="-20 20" />
      <motor name="r_ankle_roll_joint" joint="r_ankle_roll_joint" gear="1" ctrllimited="true" ctrlrange="-20 20" />
   </actuator>

    <sensor>
      <!-- Position sensors -->
      <actuatorpos name="l_hip_pitch_joint_p" actuator="l_hip_pitch_joint" user="13"/>
      <actuatorpos name="l_hip_roll_joint_p" actuator="l_hip_roll_joint" user="13"/>
      <actuatorpos name="l_thigh_joint_p" actuator="l_thigh_joint" user="13"/>
      <actuatorpos name="l_calf_joint_p" actuator="l_calf_joint" user="13"/>
      <actuatorpos name="l_ankle_pitch_joint_p" actuator="l_ankle_pitch_joint" user="13"/>
      <actuatorpos name="l_ankle_roll_joint_p" actuator="l_ankle_roll_joint" user="13"/>

      <actuatorpos name="r_hip_pitch_joint_p" actuator="r_hip_pitch_joint" user="13"/>
      <actuatorpos name="r_hip_roll_joint_p" actuator="r_hip_roll_joint" user="13"/>
      <actuatorpos name="r_thigh_joint_p" actuator="r_thigh_joint" user="13"/>
      <actuatorpos name="r_calf_joint_p" actuator="r_calf_joint" user="13"/>
      <actuatorpos name="r_ankle_pitch_joint_p" actuator="r_ankle_pitch_joint" user="13"/>
      <actuatorpos name="r_ankle_roll_joint_p" actuator="r_ankle_roll_joint" user="13"/>
  
      <!-- Velocity sensors -->
      <actuatorvel name="l_hip_pitch_joint_v" actuator="l_hip_pitch_joint" user="13" noise="1e-3"/>
      <actuatorvel name="l_hip_roll_joint_v" actuator="l_hip_roll_joint" user="13" noise="1e-3"/>
      <actuatorvel name="l_thigh_joint_v" actuator="l_thigh_joint" user="13" noise="1e-3"/>
      <actuatorvel name="l_calf_joint_v" actuator="l_calf_joint" user="13" noise="1e-3"/>
      <actuatorvel name="l_ankle_pitch_joint_v" actuator="l_ankle_pitch_joint" user="13" noise="1e-3"/>
      <actuatorvel name="l_ankle_roll_joint_v" actuator="l_ankle_roll_joint" user="13" noise="1e-3"/>

      <actuatorvel name="r_hip_pitch_joint_v" actuator="r_hip_pitch_joint" user="13" noise="1e-3"/>
      <actuatorvel name="r_hip_roll_joint_v" actuator="r_hip_roll_joint" user="13" noise="1e-3"/>
      <actuatorvel name="r_thigh_joint_v" actuator="r_thigh_joint" user="13" noise="1e-3"/>
      <actuatorvel name="r_calf_joint_v" actuator="r_calf_joint" user="13" noise="1e-3"/>
      <actuatorvel name="r_ankle_pitch_joint_v" actuator="r_ankle_pitch_joint" user="13" noise="1e-3"/>
      <actuatorvel name="r_ankle_roll_joint_v" actuator="r_ankle_roll_joint" user="13" noise="1e-3"/>

      <!-- Force sensors -->
      <actuatorfrc name="l_hip_pitch_joint_f" actuator="l_hip_pitch_joint" user="13" noise="1e-3"/>
      <actuatorfrc name="l_hip_roll_joint_f" actuator="l_hip_roll_joint" user="13" noise="1e-3"/>
      <actuatorfrc name="l_thigh_joint_f" actuator="l_thigh_joint" user="13" noise="1e-3"/>
      <actuatorfrc name="l_calf_joint_f" actuator="l_calf_joint" user="13" noise="1e-3"/>
      <actuatorfrc name="l_ankle_pitch_joint_f" actuator="l_ankle_pitch_joint" user="13" noise="1e-3"/>
      <actuatorfrc name="l_ankle_roll_joint_f" actuator="l_ankle_roll_joint" user="13" noise="1e-3"/>

      <actuatorfrc name="r_hip_pitch_joint_f" actuator="r_hip_pitch_joint" user="13" noise="1e-3"/>
      <actuatorfrc name="r_hip_roll_joint_f" actuator="r_hip_roll_joint" user="13" noise="1e-3"/>
      <actuatorfrc name="r_thigh_joint_f" actuator="r_thigh_joint" user="13" noise="1e-3"/>
      <actuatorfrc name="r_calf_joint_f" actuator="r_calf_joint" user="13" noise="1e-3"/>
      <actuatorfrc name="r_ankle_pitch_joint_f" actuator="r_ankle_pitch_joint" user="13" noise="1e-3"/>
      <actuatorfrc name="r_ankle_roll_joint_f" actuator="r_ankle_roll_joint" user="13" noise="1e-3"/>

      <framequat name='orientation' objtype='site' noise='0.001' objname='imu'/>
      <framepos name='position' objtype='site' noise='0.001' objname='imu'/>
      <gyro name='angular-velocity' site='imu' noise='0.005' cutoff='34.9'/>
      <velocimeter name='linear-velocity' site='imu' noise='0.001' cutoff='30'/>
      <accelerometer name='linear-acceleration' site='imu' noise='0.005' cutoff='157'/>
      <magnetometer name='magnetometer' site='imu'/>
    </sensor>

   <!-- setup scene --> 
  <statistic center="1.0 0.7 1.0" extent="0.8"/>
  <visual>
    <headlight diffuse="0.6 0.6 0.6" ambient="0.1 0.1 0.1" specular="0.9 0.9 0.9"/>
    <rgba haze="0.15 0.25 0.35 1"/>
    <global azimuth="-140" elevation="-20"/>
  </visual>
  <asset>
    <texture type="skybox" builtin="flat" rgb1="0 0 0" rgb2="0 0 0" width="512" height="3072"/>
    <texture type="2d" name="groundplane" builtin="checker" mark="edge" rgb1="0.2 0.3 0.4" rgb2="0.1 0.2 0.3" markrgb="0.8 0.8 0.8" width="300" height="300"/>
    <material name="groundplane" texture="groundplane" texuniform="true" texrepeat="5 5" reflectance="0.2"/>
  </asset>
  <worldbody>
    <light pos="1 0 3.5" dir="0 0 -1" directional="true"/>
    <geom contype="15" conaffinity="15"  name="floor" size="0 0 0.05" type="plane" material="groundplane"/>
  </worldbody>

</mujoco>
